[2025-08-17T14:25:27.837+0200] {local_task_job_runner.py:120} INFO - ::group::Pre task execution logs
[2025-08-17T14:25:27.859+0200] {taskinstance.py:2076} INFO - Dependencies all met for dep_context=non-requeueable deps ti=<TaskInstance: push_all_raw_files_to_s3.dvc_add_and_push manual__2025-08-17T12:25:21.090970+00:00 [queued]>
[2025-08-17T14:25:27.865+0200] {taskinstance.py:2076} INFO - Dependencies all met for dep_context=requeueable deps ti=<TaskInstance: push_all_raw_files_to_s3.dvc_add_and_push manual__2025-08-17T12:25:21.090970+00:00 [queued]>
[2025-08-17T14:25:27.865+0200] {taskinstance.py:2306} INFO - Starting attempt 1 of 2
[2025-08-17T14:25:27.891+0200] {taskinstance.py:2330} INFO - Executing <Task(BashOperator): dvc_add_and_push> on 2025-08-17 12:25:21.090970+00:00
[2025-08-17T14:25:27.893+0200] {standard_task_runner.py:64} INFO - Started process 48755 to run task
[2025-08-17T14:25:27.897+0200] {standard_task_runner.py:90} INFO - Running: ['airflow', 'tasks', 'run', 'push_all_raw_files_to_s3', 'dvc_add_and_push', 'manual__2025-08-17T12:25:21.090970+00:00', '--job-id', '9', '--raw', '--subdir', 'DAGS_FOLDER/push_all_raw_files_to_s3.py', '--cfg-path', '/tmp/tmpezspoo4k']
[2025-08-17T14:25:27.899+0200] {standard_task_runner.py:91} INFO - Job 9: Subtask dvc_add_and_push
[2025-08-17T14:25:27.936+0200] {task_command.py:426} INFO - Running <TaskInstance: push_all_raw_files_to_s3.dvc_add_and_push manual__2025-08-17T12:25:21.090970+00:00 [running]> on host raspberrypi
[2025-08-17T14:25:28.002+0200] {taskinstance.py:2648} INFO - Exporting env vars: AIRFLOW_CTX_DAG_OWNER='Allister Kohn' AIRFLOW_CTX_DAG_ID='push_all_raw_files_to_s3' AIRFLOW_CTX_TASK_ID='dvc_add_and_push' AIRFLOW_CTX_EXECUTION_DATE='2025-08-17T12:25:21.090970+00:00' AIRFLOW_CTX_TRY_NUMBER='1' AIRFLOW_CTX_DAG_RUN_ID='manual__2025-08-17T12:25:21.090970+00:00'
[2025-08-17T14:25:28.003+0200] {taskinstance.py:430} INFO - ::endgroup::
[2025-08-17T14:25:28.014+0200] {subprocess.py:63} INFO - Tmp dir root location: /tmp
[2025-08-17T14:25:28.014+0200] {subprocess.py:75} INFO - Running command: ['/usr/bin/bash', '-c', '\n            /home/allisterkohn/.pyenv/versions/velib_env/bin/dvc add "data/station_status/raw/2025/08/16"\n            /home/allisterkohn/.pyenv/versions/velib_env/bin/dvc push\n        ']
[2025-08-17T14:25:28.019+0200] {subprocess.py:86} INFO - Output:
[2025-08-17T14:25:28.221+0200] {subprocess.py:93} INFO - Traceback (most recent call last):
[2025-08-17T14:25:28.221+0200] {subprocess.py:93} INFO -   File "/home/allisterkohn/.pyenv/versions/velib_env/lib/python3.11/site-packages/dvc/cli/__init__.py", line 210, in main
[2025-08-17T14:25:28.221+0200] {subprocess.py:93} INFO -     cmd = args.func(args)
[2025-08-17T14:25:28.221+0200] {subprocess.py:93} INFO -           ^^^^^^^^^^^^^^^
[2025-08-17T14:25:28.222+0200] {subprocess.py:93} INFO -   File "/home/allisterkohn/.pyenv/versions/velib_env/lib/python3.11/site-packages/dvc/cli/command.py", line 17, in __init__
[2025-08-17T14:25:28.222+0200] {subprocess.py:93} INFO -     from dvc.repo import Repo
[2025-08-17T14:25:28.222+0200] {subprocess.py:93} INFO -   File "/home/allisterkohn/.pyenv/versions/velib_env/lib/python3.11/site-packages/dvc/repo/__init__.py", line 14, in <module>
[2025-08-17T14:25:28.222+0200] {subprocess.py:93} INFO -     from dvc.ignore import DvcIgnoreFilter
[2025-08-17T14:25:28.222+0200] {subprocess.py:93} INFO -   File "/home/allisterkohn/.pyenv/versions/velib_env/lib/python3.11/site-packages/dvc/ignore.py", line 11, in <module>
[2025-08-17T14:25:28.222+0200] {subprocess.py:93} INFO -     from dvc.fs import Schemes, localfs
[2025-08-17T14:25:28.222+0200] {subprocess.py:93} INFO -   File "/home/allisterkohn/.pyenv/versions/velib_env/lib/python3.11/site-packages/dvc/fs/__init__.py", line 8, in <module>
[2025-08-17T14:25:28.222+0200] {subprocess.py:93} INFO -     from dvc_http import HTTPFileSystem, HTTPSFileSystem  # noqa: F401
[2025-08-17T14:25:28.222+0200] {subprocess.py:93} INFO -     ^^^^^^^^^^^^^^^^^^^^^^^^^^^^^^^^^^^^^^^^^^^^^^^^^^^^
[2025-08-17T14:25:28.222+0200] {subprocess.py:93} INFO -   File "/home/allisterkohn/.pyenv/versions/velib_env/lib/python3.11/site-packages/dvc_http/__init__.py", line 6, in <module>
[2025-08-17T14:25:28.222+0200] {subprocess.py:93} INFO -     from dvc_objects.fs.base import FileSystem
[2025-08-17T14:25:28.222+0200] {subprocess.py:93} INFO -   File "/home/allisterkohn/.pyenv/versions/velib_env/lib/python3.11/site-packages/dvc_objects/fs/__init__.py", line 5, in <module>
[2025-08-17T14:25:28.222+0200] {subprocess.py:93} INFO -     from . import generic  # noqa: F401
[2025-08-17T14:25:28.222+0200] {subprocess.py:93} INFO -     ^^^^^^^^^^^^^^^^^^^^^
[2025-08-17T14:25:28.222+0200] {subprocess.py:93} INFO -   File "/home/allisterkohn/.pyenv/versions/velib_env/lib/python3.11/site-packages/dvc_objects/fs/generic.py", line 10, in <module>
[2025-08-17T14:25:28.223+0200] {subprocess.py:93} INFO -     from fsspec.callbacks import DEFAULT_CALLBACK
[2025-08-17T14:25:28.223+0200] {subprocess.py:93} INFO - ImportError: cannot import name 'DEFAULT_CALLBACK' from 'fsspec.callbacks' (/home/allisterkohn/.pyenv/versions/velib_env/lib/python3.11/site-packages/fsspec/callbacks.py)
[2025-08-17T14:25:28.223+0200] {subprocess.py:93} INFO - 
[2025-08-17T14:25:28.223+0200] {subprocess.py:93} INFO - During handling of the above exception, another exception occurred:
[2025-08-17T14:25:28.223+0200] {subprocess.py:93} INFO - 
[2025-08-17T14:25:28.223+0200] {subprocess.py:93} INFO - Traceback (most recent call last):
[2025-08-17T14:25:28.223+0200] {subprocess.py:93} INFO -   File "/home/allisterkohn/.pyenv/versions/velib_env/bin/dvc", line 8, in <module>
[2025-08-17T14:25:28.223+0200] {subprocess.py:93} INFO -     sys.exit(main())
[2025-08-17T14:25:28.223+0200] {subprocess.py:93} INFO -              ^^^^^^
[2025-08-17T14:25:28.223+0200] {subprocess.py:93} INFO -   File "/home/allisterkohn/.pyenv/versions/velib_env/lib/python3.11/site-packages/dvc/cli/__init__.py", line 236, in main
[2025-08-17T14:25:28.223+0200] {subprocess.py:93} INFO -     ret = _log_exceptions(exc) or 255
[2025-08-17T14:25:28.223+0200] {subprocess.py:93} INFO -           ^^^^^^^^^^^^^^^^^^^^
[2025-08-17T14:25:28.223+0200] {subprocess.py:93} INFO -   File "/home/allisterkohn/.pyenv/versions/velib_env/lib/python3.11/site-packages/dvc/cli/__init__.py", line 77, in _log_exceptions
[2025-08-17T14:25:28.223+0200] {subprocess.py:93} INFO -     from dvc.fs import AuthError, ConfigError, RemoteMissingDepsError
[2025-08-17T14:25:28.223+0200] {subprocess.py:93} INFO -   File "/home/allisterkohn/.pyenv/versions/velib_env/lib/python3.11/site-packages/dvc/fs/__init__.py", line 8, in <module>
[2025-08-17T14:25:28.223+0200] {subprocess.py:93} INFO -     from dvc_http import HTTPFileSystem, HTTPSFileSystem  # noqa: F401
[2025-08-17T14:25:28.224+0200] {subprocess.py:93} INFO -     ^^^^^^^^^^^^^^^^^^^^^^^^^^^^^^^^^^^^^^^^^^^^^^^^^^^^
[2025-08-17T14:25:28.224+0200] {subprocess.py:93} INFO -   File "/home/allisterkohn/.pyenv/versions/velib_env/lib/python3.11/site-packages/dvc_http/__init__.py", line 6, in <module>
[2025-08-17T14:25:28.224+0200] {subprocess.py:93} INFO -     from dvc_objects.fs.base import FileSystem
[2025-08-17T14:25:28.224+0200] {subprocess.py:93} INFO -   File "/home/allisterkohn/.pyenv/versions/velib_env/lib/python3.11/site-packages/dvc_objects/fs/__init__.py", line 5, in <module>
[2025-08-17T14:25:28.224+0200] {subprocess.py:93} INFO -     from . import generic  # noqa: F401
[2025-08-17T14:25:28.224+0200] {subprocess.py:93} INFO -     ^^^^^^^^^^^^^^^^^^^^^
[2025-08-17T14:25:28.224+0200] {subprocess.py:93} INFO -   File "/home/allisterkohn/.pyenv/versions/velib_env/lib/python3.11/site-packages/dvc_objects/fs/generic.py", line 10, in <module>
[2025-08-17T14:25:28.224+0200] {subprocess.py:93} INFO -     from fsspec.callbacks import DEFAULT_CALLBACK
[2025-08-17T14:25:28.224+0200] {subprocess.py:93} INFO - ImportError: cannot import name 'DEFAULT_CALLBACK' from 'fsspec.callbacks' (/home/allisterkohn/.pyenv/versions/velib_env/lib/python3.11/site-packages/fsspec/callbacks.py)
[2025-08-17T14:25:28.490+0200] {subprocess.py:93} INFO - Traceback (most recent call last):
[2025-08-17T14:25:28.491+0200] {subprocess.py:93} INFO -   File "/home/allisterkohn/.pyenv/versions/velib_env/lib/python3.11/site-packages/dvc/cli/__init__.py", line 210, in main
[2025-08-17T14:25:28.491+0200] {subprocess.py:93} INFO -     cmd = args.func(args)
[2025-08-17T14:25:28.491+0200] {subprocess.py:93} INFO -           ^^^^^^^^^^^^^^^
[2025-08-17T14:25:28.491+0200] {subprocess.py:93} INFO -   File "/home/allisterkohn/.pyenv/versions/velib_env/lib/python3.11/site-packages/dvc/cli/command.py", line 17, in __init__
[2025-08-17T14:25:28.491+0200] {subprocess.py:93} INFO -     from dvc.repo import Repo
[2025-08-17T14:25:28.491+0200] {subprocess.py:93} INFO -   File "/home/allisterkohn/.pyenv/versions/velib_env/lib/python3.11/site-packages/dvc/repo/__init__.py", line 14, in <module>
[2025-08-17T14:25:28.491+0200] {subprocess.py:93} INFO -     from dvc.ignore import DvcIgnoreFilter
[2025-08-17T14:25:28.491+0200] {subprocess.py:93} INFO -   File "/home/allisterkohn/.pyenv/versions/velib_env/lib/python3.11/site-packages/dvc/ignore.py", line 11, in <module>
[2025-08-17T14:25:28.491+0200] {subprocess.py:93} INFO -     from dvc.fs import Schemes, localfs
[2025-08-17T14:25:28.491+0200] {subprocess.py:93} INFO -   File "/home/allisterkohn/.pyenv/versions/velib_env/lib/python3.11/site-packages/dvc/fs/__init__.py", line 8, in <module>
[2025-08-17T14:25:28.491+0200] {subprocess.py:93} INFO -     from dvc_http import HTTPFileSystem, HTTPSFileSystem  # noqa: F401
[2025-08-17T14:25:28.492+0200] {subprocess.py:93} INFO -     ^^^^^^^^^^^^^^^^^^^^^^^^^^^^^^^^^^^^^^^^^^^^^^^^^^^^
[2025-08-17T14:25:28.492+0200] {subprocess.py:93} INFO -   File "/home/allisterkohn/.pyenv/versions/velib_env/lib/python3.11/site-packages/dvc_http/__init__.py", line 6, in <module>
[2025-08-17T14:25:28.492+0200] {subprocess.py:93} INFO -     from dvc_objects.fs.base import FileSystem
[2025-08-17T14:25:28.492+0200] {subprocess.py:93} INFO -   File "/home/allisterkohn/.pyenv/versions/velib_env/lib/python3.11/site-packages/dvc_objects/fs/__init__.py", line 5, in <module>
[2025-08-17T14:25:28.492+0200] {subprocess.py:93} INFO -     from . import generic  # noqa: F401
[2025-08-17T14:25:28.492+0200] {subprocess.py:93} INFO -     ^^^^^^^^^^^^^^^^^^^^^
[2025-08-17T14:25:28.492+0200] {subprocess.py:93} INFO -   File "/home/allisterkohn/.pyenv/versions/velib_env/lib/python3.11/site-packages/dvc_objects/fs/generic.py", line 10, in <module>
[2025-08-17T14:25:28.492+0200] {subprocess.py:93} INFO -     from fsspec.callbacks import DEFAULT_CALLBACK
[2025-08-17T14:25:28.492+0200] {subprocess.py:93} INFO - ImportError: cannot import name 'DEFAULT_CALLBACK' from 'fsspec.callbacks' (/home/allisterkohn/.pyenv/versions/velib_env/lib/python3.11/site-packages/fsspec/callbacks.py)
[2025-08-17T14:25:28.492+0200] {subprocess.py:93} INFO - 
[2025-08-17T14:25:28.492+0200] {subprocess.py:93} INFO - During handling of the above exception, another exception occurred:
[2025-08-17T14:25:28.492+0200] {subprocess.py:93} INFO - 
[2025-08-17T14:25:28.492+0200] {subprocess.py:93} INFO - Traceback (most recent call last):
[2025-08-17T14:25:28.492+0200] {subprocess.py:93} INFO -   File "/home/allisterkohn/.pyenv/versions/velib_env/bin/dvc", line 8, in <module>
[2025-08-17T14:25:28.492+0200] {subprocess.py:93} INFO -     sys.exit(main())
[2025-08-17T14:25:28.492+0200] {subprocess.py:93} INFO -              ^^^^^^
[2025-08-17T14:25:28.493+0200] {subprocess.py:93} INFO -   File "/home/allisterkohn/.pyenv/versions/velib_env/lib/python3.11/site-packages/dvc/cli/__init__.py", line 236, in main
[2025-08-17T14:25:28.493+0200] {subprocess.py:93} INFO -     ret = _log_exceptions(exc) or 255
[2025-08-17T14:25:28.493+0200] {subprocess.py:93} INFO -           ^^^^^^^^^^^^^^^^^^^^
[2025-08-17T14:25:28.493+0200] {subprocess.py:93} INFO -   File "/home/allisterkohn/.pyenv/versions/velib_env/lib/python3.11/site-packages/dvc/cli/__init__.py", line 77, in _log_exceptions
[2025-08-17T14:25:28.493+0200] {subprocess.py:93} INFO -     from dvc.fs import AuthError, ConfigError, RemoteMissingDepsError
[2025-08-17T14:25:28.493+0200] {subprocess.py:93} INFO -   File "/home/allisterkohn/.pyenv/versions/velib_env/lib/python3.11/site-packages/dvc/fs/__init__.py", line 8, in <module>
[2025-08-17T14:25:28.493+0200] {subprocess.py:93} INFO -     from dvc_http import HTTPFileSystem, HTTPSFileSystem  # noqa: F401
[2025-08-17T14:25:28.493+0200] {subprocess.py:93} INFO -     ^^^^^^^^^^^^^^^^^^^^^^^^^^^^^^^^^^^^^^^^^^^^^^^^^^^^
[2025-08-17T14:25:28.493+0200] {subprocess.py:93} INFO -   File "/home/allisterkohn/.pyenv/versions/velib_env/lib/python3.11/site-packages/dvc_http/__init__.py", line 6, in <module>
[2025-08-17T14:25:28.493+0200] {subprocess.py:93} INFO -     from dvc_objects.fs.base import FileSystem
[2025-08-17T14:25:28.493+0200] {subprocess.py:93} INFO -   File "/home/allisterkohn/.pyenv/versions/velib_env/lib/python3.11/site-packages/dvc_objects/fs/__init__.py", line 5, in <module>
[2025-08-17T14:25:28.493+0200] {subprocess.py:93} INFO -     from . import generic  # noqa: F401
[2025-08-17T14:25:28.493+0200] {subprocess.py:93} INFO -     ^^^^^^^^^^^^^^^^^^^^^
[2025-08-17T14:25:28.493+0200] {subprocess.py:93} INFO -   File "/home/allisterkohn/.pyenv/versions/velib_env/lib/python3.11/site-packages/dvc_objects/fs/generic.py", line 10, in <module>
[2025-08-17T14:25:28.493+0200] {subprocess.py:93} INFO -     from fsspec.callbacks import DEFAULT_CALLBACK
[2025-08-17T14:25:28.493+0200] {subprocess.py:93} INFO - ImportError: cannot import name 'DEFAULT_CALLBACK' from 'fsspec.callbacks' (/home/allisterkohn/.pyenv/versions/velib_env/lib/python3.11/site-packages/fsspec/callbacks.py)
[2025-08-17T14:25:28.558+0200] {subprocess.py:97} INFO - Command exited with return code 1
[2025-08-17T14:25:28.558+0200] {taskinstance.py:441} INFO - ::group::Post task execution logs
[2025-08-17T14:25:28.563+0200] {taskinstance.py:2905} ERROR - Task failed with exception
Traceback (most recent call last):
  File "/home/allisterkohn/.pyenv/versions/velib_env/lib/python3.11/site-packages/airflow/models/taskinstance.py", line 465, in _execute_task
    result = _execute_callable(context=context, **execute_callable_kwargs)
             ^^^^^^^^^^^^^^^^^^^^^^^^^^^^^^^^^^^^^^^^^^^^^^^^^^^^^^^^^^^^^
  File "/home/allisterkohn/.pyenv/versions/velib_env/lib/python3.11/site-packages/airflow/models/taskinstance.py", line 432, in _execute_callable
    return execute_callable(context=context, **execute_callable_kwargs)
           ^^^^^^^^^^^^^^^^^^^^^^^^^^^^^^^^^^^^^^^^^^^^^^^^^^^^^^^^^^^^
  File "/home/allisterkohn/.pyenv/versions/velib_env/lib/python3.11/site-packages/airflow/models/baseoperator.py", line 401, in wrapper
    return func(self, *args, **kwargs)
           ^^^^^^^^^^^^^^^^^^^^^^^^^^^
  File "/home/allisterkohn/.pyenv/versions/velib_env/lib/python3.11/site-packages/airflow/operators/bash.py", line 243, in execute
    raise AirflowException(
airflow.exceptions.AirflowException: Bash command failed. The command returned a non-zero exit code 1.
[2025-08-17T14:25:28.566+0200] {taskinstance.py:1206} INFO - Marking task as UP_FOR_RETRY. dag_id=push_all_raw_files_to_s3, task_id=dvc_add_and_push, run_id=manual__2025-08-17T12:25:21.090970+00:00, execution_date=20250817T122521, start_date=20250817T122527, end_date=20250817T122528
[2025-08-17T14:25:28.586+0200] {standard_task_runner.py:110} ERROR - Failed to execute job 9 for task dvc_add_and_push (Bash command failed. The command returned a non-zero exit code 1.; 48755)
[2025-08-17T14:25:28.591+0200] {local_task_job_runner.py:243} INFO - Task exited with return code 1
[2025-08-17T14:25:28.600+0200] {taskinstance.py:3503} INFO - 0 downstream tasks scheduled from follow-on schedule check
[2025-08-17T14:25:28.604+0200] {local_task_job_runner.py:222} INFO - ::endgroup::
